[2023-12-10 22:36:38,913] {taskinstance.py:1159} INFO - Dependencies all met for <TaskInstance: pipeline.fit_model manual__2023-12-10T17:36:27.742952+00:00 [queued]>
[2023-12-10 22:36:38,918] {taskinstance.py:1159} INFO - Dependencies all met for <TaskInstance: pipeline.fit_model manual__2023-12-10T17:36:27.742952+00:00 [queued]>
[2023-12-10 22:36:38,918] {taskinstance.py:1356} INFO - 
--------------------------------------------------------------------------------
[2023-12-10 22:36:38,918] {taskinstance.py:1357} INFO - Starting attempt 1 of 6
[2023-12-10 22:36:38,918] {taskinstance.py:1358} INFO - 
--------------------------------------------------------------------------------
[2023-12-10 22:36:38,930] {taskinstance.py:1377} INFO - Executing <Task(BashOperator): fit_model> on 2023-12-10 17:36:27.742952+00:00
[2023-12-10 22:36:38,932] {standard_task_runner.py:52} INFO - Started process 25619 to run task
[2023-12-10 22:36:38,938] {standard_task_runner.py:79} INFO - Running: ['airflow', 'tasks', 'run', 'pipeline', 'fit_model', 'manual__2023-12-10T17:36:27.742952+00:00', '--job-id', '23', '--raw', '--subdir', 'DAGS_FOLDER/final_script.py', '--cfg-path', '/tmp/tmp_rcic7yj', '--error-file', '/tmp/tmpferq1qm2']
[2023-12-10 22:36:38,938] {standard_task_runner.py:80} INFO - Job 23: Subtask fit_model
[2023-12-10 22:36:38,973] {task_command.py:369} INFO - Running <TaskInstance: pipeline.fit_model manual__2023-12-10T17:36:27.742952+00:00 [running]> on host vmac-VirtualBox
[2023-12-10 22:36:39,020] {taskinstance.py:1569} INFO - Exporting the following env vars:
AIRFLOW_CTX_DAG_OWNER=Admin
AIRFLOW_CTX_DAG_ID=pipeline
AIRFLOW_CTX_TASK_ID=fit_model
AIRFLOW_CTX_EXECUTION_DATE=2023-12-10T17:36:27.742952+00:00
AIRFLOW_CTX_TRY_NUMBER=1
AIRFLOW_CTX_DAG_RUN_ID=manual__2023-12-10T17:36:27.742952+00:00
[2023-12-10 22:36:39,020] {subprocess.py:62} INFO - Tmp dir root location: 
 /tmp
[2023-12-10 22:36:39,023] {subprocess.py:74} INFO - Running command: ['bash', '-c', 'python3 /home/vmac/lab3/scripts/fit_model.py']
[2023-12-10 22:36:39,034] {subprocess.py:85} INFO - Output:
[2023-12-10 22:37:42,603] {subprocess.py:92} INFO - Traceback (most recent call last):
[2023-12-10 22:37:42,603] {subprocess.py:92} INFO -   File "/home/vmac/lab3/lab3/lib/python3.10/site-packages/urllib3/connection.py", line 203, in _new_conn
[2023-12-10 22:37:42,678] {subprocess.py:92} INFO -     sock = connection.create_connection(
[2023-12-10 22:37:42,678] {subprocess.py:92} INFO -   File "/home/vmac/lab3/lab3/lib/python3.10/site-packages/urllib3/util/connection.py", line 85, in create_connection
[2023-12-10 22:37:42,680] {subprocess.py:92} INFO -     raise err
[2023-12-10 22:37:42,680] {subprocess.py:92} INFO -   File "/home/vmac/lab3/lab3/lib/python3.10/site-packages/urllib3/util/connection.py", line 73, in create_connection
[2023-12-10 22:37:42,680] {subprocess.py:92} INFO -     sock.connect(sa)
[2023-12-10 22:37:42,680] {subprocess.py:92} INFO - ConnectionRefusedError: [Errno 111] Connection refused
[2023-12-10 22:37:42,680] {subprocess.py:92} INFO - 
[2023-12-10 22:37:42,680] {subprocess.py:92} INFO - The above exception was the direct cause of the following exception:
[2023-12-10 22:37:42,680] {subprocess.py:92} INFO - 
[2023-12-10 22:37:42,680] {subprocess.py:92} INFO - Traceback (most recent call last):
[2023-12-10 22:37:42,680] {subprocess.py:92} INFO -   File "/home/vmac/lab3/lab3/lib/python3.10/site-packages/urllib3/connectionpool.py", line 790, in urlopen
[2023-12-10 22:37:42,681] {subprocess.py:92} INFO -     response = self._make_request(
[2023-12-10 22:37:42,681] {subprocess.py:92} INFO -   File "/home/vmac/lab3/lab3/lib/python3.10/site-packages/urllib3/connectionpool.py", line 496, in _make_request
[2023-12-10 22:37:42,681] {subprocess.py:92} INFO -     conn.request(
[2023-12-10 22:37:42,681] {subprocess.py:92} INFO -   File "/home/vmac/lab3/lab3/lib/python3.10/site-packages/urllib3/connection.py", line 395, in request
[2023-12-10 22:37:42,681] {subprocess.py:92} INFO -     self.endheaders()
[2023-12-10 22:37:42,681] {subprocess.py:92} INFO -   File "/usr/lib/python3.10/http/client.py", line 1278, in endheaders
[2023-12-10 22:37:42,698] {subprocess.py:92} INFO -     self._send_output(message_body, encode_chunked=encode_chunked)
[2023-12-10 22:37:42,698] {subprocess.py:92} INFO -   File "/usr/lib/python3.10/http/client.py", line 1038, in _send_output
[2023-12-10 22:37:42,698] {subprocess.py:92} INFO -     self.send(msg)
[2023-12-10 22:37:42,698] {subprocess.py:92} INFO -   File "/usr/lib/python3.10/http/client.py", line 976, in send
[2023-12-10 22:37:42,698] {subprocess.py:92} INFO -     self.connect()
[2023-12-10 22:37:42,698] {subprocess.py:92} INFO -   File "/home/vmac/lab3/lab3/lib/python3.10/site-packages/urllib3/connection.py", line 243, in connect
[2023-12-10 22:37:42,698] {subprocess.py:92} INFO -     self.sock = self._new_conn()
[2023-12-10 22:37:42,698] {subprocess.py:92} INFO -   File "/home/vmac/lab3/lab3/lib/python3.10/site-packages/urllib3/connection.py", line 218, in _new_conn
[2023-12-10 22:37:42,698] {subprocess.py:92} INFO -     raise NewConnectionError(
[2023-12-10 22:37:42,698] {subprocess.py:92} INFO - urllib3.exceptions.NewConnectionError: <urllib3.connection.HTTPConnection object at 0x7f84de18d6c0>: Failed to establish a new connection: [Errno 111] Connection refused
[2023-12-10 22:37:42,698] {subprocess.py:92} INFO - 
[2023-12-10 22:37:42,698] {subprocess.py:92} INFO - The above exception was the direct cause of the following exception:
[2023-12-10 22:37:42,698] {subprocess.py:92} INFO - 
[2023-12-10 22:37:42,698] {subprocess.py:92} INFO - Traceback (most recent call last):
[2023-12-10 22:37:42,698] {subprocess.py:92} INFO -   File "/home/vmac/lab3/lab3/lib/python3.10/site-packages/requests/adapters.py", line 486, in send
[2023-12-10 22:37:42,719] {subprocess.py:92} INFO -     resp = conn.urlopen(
[2023-12-10 22:37:42,719] {subprocess.py:92} INFO -   File "/home/vmac/lab3/lab3/lib/python3.10/site-packages/urllib3/connectionpool.py", line 874, in urlopen
[2023-12-10 22:37:42,719] {subprocess.py:92} INFO -     return self.urlopen(
[2023-12-10 22:37:42,720] {subprocess.py:92} INFO -   File "/home/vmac/lab3/lab3/lib/python3.10/site-packages/urllib3/connectionpool.py", line 874, in urlopen
[2023-12-10 22:37:42,720] {subprocess.py:92} INFO -     return self.urlopen(
[2023-12-10 22:37:42,720] {subprocess.py:92} INFO -   File "/home/vmac/lab3/lab3/lib/python3.10/site-packages/urllib3/connectionpool.py", line 874, in urlopen
[2023-12-10 22:37:42,720] {subprocess.py:92} INFO -     return self.urlopen(
[2023-12-10 22:37:42,720] {subprocess.py:92} INFO -   [Previous line repeated 2 more times]
[2023-12-10 22:37:42,720] {subprocess.py:92} INFO -   File "/home/vmac/lab3/lab3/lib/python3.10/site-packages/urllib3/connectionpool.py", line 844, in urlopen
[2023-12-10 22:37:42,720] {subprocess.py:92} INFO -     retries = retries.increment(
[2023-12-10 22:37:42,720] {subprocess.py:92} INFO -   File "/home/vmac/lab3/lab3/lib/python3.10/site-packages/urllib3/util/retry.py", line 515, in increment
[2023-12-10 22:37:42,720] {subprocess.py:92} INFO -     raise MaxRetryError(_pool, url, reason) from reason  # type: ignore[arg-type]
[2023-12-10 22:37:42,720] {subprocess.py:92} INFO - urllib3.exceptions.MaxRetryError: HTTPConnectionPool(host='localhost', port=5000): Max retries exceeded with url: /api/2.0/mlflow/experiments/get-by-name?experiment_name=model_preparation (Caused by NewConnectionError('<urllib3.connection.HTTPConnection object at 0x7f84de18d6c0>: Failed to establish a new connection: [Errno 111] Connection refused'))
[2023-12-10 22:37:42,720] {subprocess.py:92} INFO - 
[2023-12-10 22:37:42,720] {subprocess.py:92} INFO - During handling of the above exception, another exception occurred:
[2023-12-10 22:37:42,720] {subprocess.py:92} INFO - 
[2023-12-10 22:37:42,720] {subprocess.py:92} INFO - Traceback (most recent call last):
[2023-12-10 22:37:42,720] {subprocess.py:92} INFO -   File "/home/vmac/lab3/lab3/lib/python3.10/site-packages/mlflow/utils/rest_utils.py", line 107, in http_request
[2023-12-10 22:37:42,720] {subprocess.py:92} INFO -     return _get_http_response_with_retries(
[2023-12-10 22:37:42,720] {subprocess.py:92} INFO -   File "/home/vmac/lab3/lab3/lib/python3.10/site-packages/mlflow/utils/request_utils.py", line 190, in _get_http_response_with_retries
[2023-12-10 22:37:42,720] {subprocess.py:92} INFO -     return session.request(method, url, **kwargs)
[2023-12-10 22:37:42,720] {subprocess.py:92} INFO -   File "/home/vmac/lab3/lab3/lib/python3.10/site-packages/requests/sessions.py", line 589, in request
[2023-12-10 22:37:42,759] {subprocess.py:92} INFO -     resp = self.send(prep, **send_kwargs)
[2023-12-10 22:37:42,759] {subprocess.py:92} INFO -   File "/home/vmac/lab3/lab3/lib/python3.10/site-packages/requests/sessions.py", line 703, in send
[2023-12-10 22:37:42,759] {subprocess.py:92} INFO -     r = adapter.send(request, **kwargs)
[2023-12-10 22:37:42,759] {subprocess.py:92} INFO -   File "/home/vmac/lab3/lab3/lib/python3.10/site-packages/requests/adapters.py", line 519, in send
[2023-12-10 22:37:42,759] {subprocess.py:92} INFO -     raise ConnectionError(e, request=request)
[2023-12-10 22:37:42,759] {subprocess.py:92} INFO - requests.exceptions.ConnectionError: HTTPConnectionPool(host='localhost', port=5000): Max retries exceeded with url: /api/2.0/mlflow/experiments/get-by-name?experiment_name=model_preparation (Caused by NewConnectionError('<urllib3.connection.HTTPConnection object at 0x7f84de18d6c0>: Failed to establish a new connection: [Errno 111] Connection refused'))
[2023-12-10 22:37:42,759] {subprocess.py:92} INFO - 
[2023-12-10 22:37:42,759] {subprocess.py:92} INFO - During handling of the above exception, another exception occurred:
[2023-12-10 22:37:42,759] {subprocess.py:92} INFO - 
[2023-12-10 22:37:42,759] {subprocess.py:92} INFO - Traceback (most recent call last):
[2023-12-10 22:37:42,759] {subprocess.py:92} INFO -   File "/home/vmac/lab3/scripts/fit_model.py", line 7, in <module>
[2023-12-10 22:37:42,759] {subprocess.py:92} INFO -     experiment = mlflow.set_experiment("model_preparation")
[2023-12-10 22:37:42,759] {subprocess.py:92} INFO -   File "/home/vmac/lab3/lab3/lib/python3.10/site-packages/mlflow/tracking/fluent.py", line 135, in set_experiment
[2023-12-10 22:37:42,759] {subprocess.py:92} INFO -     experiment = client.get_experiment_by_name(experiment_name)
[2023-12-10 22:37:42,759] {subprocess.py:92} INFO -   File "/home/vmac/lab3/lab3/lib/python3.10/site-packages/mlflow/tracking/client.py", line 520, in get_experiment_by_name
[2023-12-10 22:37:42,759] {subprocess.py:92} INFO -     return self._tracking_client.get_experiment_by_name(name)
[2023-12-10 22:37:42,759] {subprocess.py:92} INFO -   File "/home/vmac/lab3/lab3/lib/python3.10/site-packages/mlflow/tracking/_tracking_service/client.py", line 221, in get_experiment_by_name
[2023-12-10 22:37:42,759] {subprocess.py:92} INFO -     return self.store.get_experiment_by_name(name)
[2023-12-10 22:37:42,759] {subprocess.py:92} INFO -   File "/home/vmac/lab3/lab3/lib/python3.10/site-packages/mlflow/store/tracking/rest_store.py", line 306, in get_experiment_by_name
[2023-12-10 22:37:42,759] {subprocess.py:92} INFO -     response_proto = self._call_endpoint(GetExperimentByName, req_body)
[2023-12-10 22:37:42,759] {subprocess.py:92} INFO -   File "/home/vmac/lab3/lab3/lib/python3.10/site-packages/mlflow/store/tracking/rest_store.py", line 59, in _call_endpoint
[2023-12-10 22:37:42,759] {subprocess.py:92} INFO -     return call_endpoint(self.get_host_creds(), endpoint, method, json_body, response_proto)
[2023-12-10 22:37:42,760] {subprocess.py:92} INFO -   File "/home/vmac/lab3/lab3/lib/python3.10/site-packages/mlflow/utils/rest_utils.py", line 215, in call_endpoint
[2023-12-10 22:37:42,760] {subprocess.py:92} INFO -     response = http_request(**call_kwargs)
[2023-12-10 22:37:42,760] {subprocess.py:92} INFO -   File "/home/vmac/lab3/lab3/lib/python3.10/site-packages/mlflow/utils/rest_utils.py", line 129, in http_request
[2023-12-10 22:37:42,760] {subprocess.py:92} INFO -     raise MlflowException(f"API request to {url} failed with exception {e}")
[2023-12-10 22:37:42,760] {subprocess.py:92} INFO - mlflow.exceptions.MlflowException: API request to http://localhost:5000/api/2.0/mlflow/experiments/get-by-name failed with exception HTTPConnectionPool(host='localhost', port=5000): Max retries exceeded with url: /api/2.0/mlflow/experiments/get-by-name?experiment_name=model_preparation (Caused by NewConnectionError('<urllib3.connection.HTTPConnection object at 0x7f84de18d6c0>: Failed to establish a new connection: [Errno 111] Connection refused'))
[2023-12-10 22:37:43,000] {subprocess.py:96} INFO - Command exited with return code 1
[2023-12-10 22:37:43,012] {taskinstance.py:1889} ERROR - Task failed with exception
Traceback (most recent call last):
  File "/home/vmac/lab3/lab3/lib/python3.10/site-packages/airflow/operators/bash.py", line 194, in execute
    raise AirflowException(
airflow.exceptions.AirflowException: Bash command failed. The command returned a non-zero exit code 1.
[2023-12-10 22:37:43,016] {taskinstance.py:1395} INFO - Marking task as UP_FOR_RETRY. dag_id=pipeline, task_id=fit_model, execution_date=20231210T173627, start_date=20231210T173638, end_date=20231210T173743
[2023-12-10 22:37:43,060] {standard_task_runner.py:92} ERROR - Failed to execute job 23 for task fit_model (Bash command failed. The command returned a non-zero exit code 1.; 25619)
[2023-12-10 22:37:43,101] {local_task_job.py:156} INFO - Task exited with return code 1
[2023-12-10 22:37:43,120] {local_task_job.py:273} INFO - 0 downstream tasks scheduled from follow-on schedule check
