[2023-12-10 21:56:17,397] {taskinstance.py:1159} INFO - Dependencies all met for <TaskInstance: pipeline.data_create manual__2023-12-10T16:56:14.440577+00:00 [queued]>
[2023-12-10 21:56:17,404] {taskinstance.py:1159} INFO - Dependencies all met for <TaskInstance: pipeline.data_create manual__2023-12-10T16:56:14.440577+00:00 [queued]>
[2023-12-10 21:56:17,405] {taskinstance.py:1356} INFO - 
--------------------------------------------------------------------------------
[2023-12-10 21:56:17,405] {taskinstance.py:1357} INFO - Starting attempt 1 of 6
[2023-12-10 21:56:17,405] {taskinstance.py:1358} INFO - 
--------------------------------------------------------------------------------
[2023-12-10 21:56:17,419] {taskinstance.py:1377} INFO - Executing <Task(BashOperator): data_create> on 2023-12-10 16:56:14.440577+00:00
[2023-12-10 21:56:17,421] {standard_task_runner.py:52} INFO - Started process 19205 to run task
[2023-12-10 21:56:17,427] {standard_task_runner.py:79} INFO - Running: ['airflow', 'tasks', 'run', 'pipeline', 'data_create', 'manual__2023-12-10T16:56:14.440577+00:00', '--job-id', '3', '--raw', '--subdir', 'DAGS_FOLDER/final_script.py', '--cfg-path', '/tmp/tmp3z2lx8ti', '--error-file', '/tmp/tmp9y0rodsh']
[2023-12-10 21:56:17,428] {standard_task_runner.py:80} INFO - Job 3: Subtask data_create
[2023-12-10 21:56:17,462] {task_command.py:369} INFO - Running <TaskInstance: pipeline.data_create manual__2023-12-10T16:56:14.440577+00:00 [running]> on host vmac-VirtualBox
[2023-12-10 21:56:17,531] {taskinstance.py:1569} INFO - Exporting the following env vars:
AIRFLOW_CTX_DAG_OWNER=Admin
AIRFLOW_CTX_DAG_ID=pipeline
AIRFLOW_CTX_TASK_ID=data_create
AIRFLOW_CTX_EXECUTION_DATE=2023-12-10T16:56:14.440577+00:00
AIRFLOW_CTX_TRY_NUMBER=1
AIRFLOW_CTX_DAG_RUN_ID=manual__2023-12-10T16:56:14.440577+00:00
[2023-12-10 21:56:17,531] {subprocess.py:62} INFO - Tmp dir root location: 
 /tmp
[2023-12-10 21:56:17,532] {subprocess.py:74} INFO - Running command: ['bash', '-c', 'python3 /home/vmac/lab3/script/data_create.py']
[2023-12-10 21:56:17,541] {subprocess.py:85} INFO - Output:
[2023-12-10 21:56:17,554] {subprocess.py:92} INFO - python3: can't open file '/home/vmac/lab3/script/data_create.py': [Errno 2] No such file or directory
[2023-12-10 21:56:17,557] {subprocess.py:96} INFO - Command exited with return code 2
[2023-12-10 21:56:17,566] {taskinstance.py:1889} ERROR - Task failed with exception
Traceback (most recent call last):
  File "/home/vmac/lab3/lab3/lib/python3.10/site-packages/airflow/operators/bash.py", line 194, in execute
    raise AirflowException(
airflow.exceptions.AirflowException: Bash command failed. The command returned a non-zero exit code 2.
[2023-12-10 21:56:17,567] {taskinstance.py:1395} INFO - Marking task as UP_FOR_RETRY. dag_id=pipeline, task_id=data_create, execution_date=20231210T165614, start_date=20231210T165617, end_date=20231210T165617
[2023-12-10 21:56:17,646] {standard_task_runner.py:92} ERROR - Failed to execute job 3 for task data_create (Bash command failed. The command returned a non-zero exit code 2.; 19205)
[2023-12-10 21:56:17,658] {local_task_job.py:156} INFO - Task exited with return code 1
[2023-12-10 21:56:17,679] {local_task_job.py:273} INFO - 0 downstream tasks scheduled from follow-on schedule check
