[2023-12-10 22:34:06,173] {taskinstance.py:1159} INFO - Dependencies all met for <TaskInstance: pipeline.fit_model manual__2023-12-10T17:33:35.926750+00:00 [queued]>
[2023-12-10 22:34:06,179] {taskinstance.py:1159} INFO - Dependencies all met for <TaskInstance: pipeline.fit_model manual__2023-12-10T17:33:35.926750+00:00 [queued]>
[2023-12-10 22:34:06,179] {taskinstance.py:1356} INFO - 
--------------------------------------------------------------------------------
[2023-12-10 22:34:06,180] {taskinstance.py:1357} INFO - Starting attempt 1 of 6
[2023-12-10 22:34:06,180] {taskinstance.py:1358} INFO - 
--------------------------------------------------------------------------------
[2023-12-10 22:34:06,201] {taskinstance.py:1377} INFO - Executing <Task(BashOperator): fit_model> on 2023-12-10 17:33:35.926750+00:00
[2023-12-10 22:34:06,206] {standard_task_runner.py:52} INFO - Started process 25414 to run task
[2023-12-10 22:34:06,210] {standard_task_runner.py:79} INFO - Running: ['airflow', 'tasks', 'run', 'pipeline', 'fit_model', 'manual__2023-12-10T17:33:35.926750+00:00', '--job-id', '20', '--raw', '--subdir', 'DAGS_FOLDER/final_script.py', '--cfg-path', '/tmp/tmpzx6uvhub', '--error-file', '/tmp/tmpqshvjxm5']
[2023-12-10 22:34:06,211] {standard_task_runner.py:80} INFO - Job 20: Subtask fit_model
[2023-12-10 22:34:06,256] {task_command.py:369} INFO - Running <TaskInstance: pipeline.fit_model manual__2023-12-10T17:33:35.926750+00:00 [running]> on host vmac-VirtualBox
[2023-12-10 22:34:06,324] {taskinstance.py:1569} INFO - Exporting the following env vars:
AIRFLOW_CTX_DAG_OWNER=Admin
AIRFLOW_CTX_DAG_ID=pipeline
AIRFLOW_CTX_TASK_ID=fit_model
AIRFLOW_CTX_EXECUTION_DATE=2023-12-10T17:33:35.926750+00:00
AIRFLOW_CTX_TRY_NUMBER=1
AIRFLOW_CTX_DAG_RUN_ID=manual__2023-12-10T17:33:35.926750+00:00
[2023-12-10 22:34:06,324] {subprocess.py:62} INFO - Tmp dir root location: 
 /tmp
[2023-12-10 22:34:06,324] {subprocess.py:74} INFO - Running command: ['bash', '-c', 'python3 /home/vmac/lab3/scripts/fit_model.py']
[2023-12-10 22:34:06,329] {subprocess.py:85} INFO - Output:
[2023-12-10 22:34:08,416] {subprocess.py:92} INFO - Traceback (most recent call last):
[2023-12-10 22:34:08,416] {subprocess.py:92} INFO -   File "/home/vmac/lab3/scripts/fit_model.py", line 4, in <module>
[2023-12-10 22:34:08,416] {subprocess.py:92} INFO -     import mlflow
[2023-12-10 22:34:08,416] {subprocess.py:92} INFO - ModuleNotFoundError: No module named 'mlflow'
[2023-12-10 22:34:08,536] {subprocess.py:96} INFO - Command exited with return code 1
[2023-12-10 22:34:08,551] {taskinstance.py:1889} ERROR - Task failed with exception
Traceback (most recent call last):
  File "/home/vmac/lab3/lab3/lib/python3.10/site-packages/airflow/operators/bash.py", line 194, in execute
    raise AirflowException(
airflow.exceptions.AirflowException: Bash command failed. The command returned a non-zero exit code 1.
[2023-12-10 22:34:08,561] {taskinstance.py:1395} INFO - Marking task as UP_FOR_RETRY. dag_id=pipeline, task_id=fit_model, execution_date=20231210T173335, start_date=20231210T173406, end_date=20231210T173408
[2023-12-10 22:34:08,573] {standard_task_runner.py:92} ERROR - Failed to execute job 20 for task fit_model (Bash command failed. The command returned a non-zero exit code 1.; 25414)
[2023-12-10 22:34:08,607] {local_task_job.py:156} INFO - Task exited with return code 1
[2023-12-10 22:34:08,633] {local_task_job.py:273} INFO - 0 downstream tasks scheduled from follow-on schedule check
